<?xml version="1.0"?>
<robot name="bumpybot_sphere">

  <link name="root">
    <inertial>
      <mass value="1.0"/>
      <!--2/5*MR^2-->
      <inertia ixx="0.645" ixy="0.0" ixz="0.0" iyy="0.645" iyz="0.0" izz="2.25"/>
    </inertial>
  </link>

  <link name="link_x">
    <inertial>
      <mass value="1.0e-3"/>
      <inertia ixx="1.0e-8" ixy="0.0" ixz="0.0" iyy="1.0e-8" iyz="0.0" izz="1.0e-8"/>
    </inertial>
    <visual>
      <geometry>
        <sphere radius="0.36" />
      </geometry>
      <material name="red">
        <color rgba="1 0 0 1" />
      </material>
    </visual>
    <collision>
      <geometry>
        <sphere radius="0.36" />
      </geometry>
    </collision>
  </link>

  <joint name="joint_x" type="revolute">
    <parent link="root" />
    <child link="link_x" />
    <origin xyz="0 0 0" rpy="0 0 0" />
    <axis xyz="1 0 0" />
  </joint>

  <link name="box">
    <inertial>
      <mass value="1.0e-3"/>
      <inertia ixx="1.0e-8" ixy="0.0" ixz="0.0" iyy="1.0e-8" iyz="0.0" izz="1.0e-8"/>
    </inertial>
  <visual>
    <geometry>
      <box size="1.0 0.2 0.2"/>
    </geometry>
  </visual>
  <collision>
    <geometry>
      <box size="1.0 0.2 0.2"/>
    </geometry>
  </collision>
</link>

<joint name="fixed", type="fixed">
  <parent link="link_x" />
    <child link="box" />
    <origin xyz="0 0 0" rpy="0 0 0" />
  </joint>


  <link name="link_y">
    <inertial>
      <mass value="1.0e-3"/>
      <inertia ixx="1.0e-8" ixy="0.0" ixz="0.0" iyy="1.0e-8" iyz="0.0" izz="1.0e-8"/>
    </inertial>
    <visual>
      <geometry>
        <cylinder radius="0.05" length="0.6" />
      </geometry>
      <material name="blue">
        <color rgba="0 0 1 1" />
      </material>
    </visual>
    <collision>
      <geometry>
        <sphere radius="0.36" />
      </geometry>
    </collision>
  </link>

  <joint name="joint_y" type="revolute">
    <parent link="box" />
    <child link="link_y" />
    <origin xyz="1 0 0" rpy="0 0 0" />
    <axis xyz="0 1 0" />
  </joint>

</robot>
