<?xml version="1.0"?>
<robot name="bumpybot">
  <link name="base">
    <inertial>
        <mass value="1e9"/>
        <inertia ixx="1" ixy="0.0" ixz="0.0" iyy="1" iyz="0.0" izz="1"/>
    </inertial>
  </link>
  
  <link name="dummy_prismatic_x_link">
    <inertial>
      <mass value="1e-9"/>
      <inertia ixx="1e-9" ixy="0.0" ixz="0.0" iyy="1e-9" iyz="0.0" izz="1e-9"/>
    </inertial>
  </link>

  <joint name="dummy_prismatic_x_joint" type="prismatic">
    <axis xyz="1 0 0"/>
    <origin rpy="0 0 0" xyz="0 0 0"/>
    <parent link="base"/>
    <child link="dummy_prismatic_x_link"/>
    <limit effort="1000.0" lower="-1e9" upper="1e9" velocity="10"/>
  </joint>

  <link name="dummy_prismatic_y_link">
    <inertial>
      <mass value="1e-9"/>
      <inertia ixx="1e-9" ixy="0.0" ixz="0.0" iyy="1e-9" iyz="0.0" izz="1e-9"/>
    </inertial>
  </link>

  <joint name="dummy_prismatic_y_joint" type="prismatic">
    <axis xyz="0 1 0"/>
    <origin rpy="0 0 0" xyz="0 0 0"/>
    <parent link="dummy_prismatic_x_link"/>
    <child link="dummy_prismatic_y_link"/>
    <limit effort="1000.0" lower="-1e9" upper="1e9" velocity="10"/>
  </joint>

  <!--<link name="dummy_revolute_yaw_link">
    <inertial>
      <mass value="1e-9"/>
      <inertia ixx="1e-9" ixy="0.0" ixz="0.0" iyy="1e-9" iyz="0.0" izz="1e-9"/>
    </inertial>
  </link>-->

  <joint name="dummy_revolute_yaw_joint" type="revolute">
    <axis xyz="0 0 1"/>
    <origin rpy="0 0 0" xyz="0 0 0"/>
    <parent link="dummy_prismatic_y_link"/>
    <child link="robot_link"/>
    <limit effort="1000.0" lower="-1e9" upper="1e9" velocity="10"/>
  </joint>

  <link name="robot_link">
    <inertial>
      <origin rpy="0 0 0" xyz="0 0 0"/>
       <mass value="20"/>
       <inertia ixx="1.13" ixy="0" ixz="0" iyy="1.13" iyz="0" izz="1.13"/> <!--0.5649801*m-->
    </inertial>
    <visual>
      <origin rpy="0 0 1.5708" xyz="0 0 0"/>
      <geometry>
        <!--<cylinder length="0.6318758" radius="0.3048"/>-->
        <mesh filename="package://meshes/bumpybot_full.stl" scale="0.0015 0.0015 0.0015"/>
      </geometry>
    </visual>
    <collision>
      <origin rpy="0 0 1.57" xyz="0 0 0"/>
      <geometry>
        <cylinder length="0.685" radius="0.3048"/>
      </geometry>
    </collision>
  </link>

  <!--<joint name="passive_prismatic_z_joint" type="prismatic">
    <axis xyz="0 0 1"/>
    <origin rpy="0 0 0" xyz="0 0 0"/>
    <parent link="dummy_revolute_yaw_link"/>
    <child link="robot_link"/>
    <limit effort="1000.0" lower="-100" upper="100" velocity="100"/>
  </joint>-->

</robot>