<?xml version="1.0" ?>
<!-- =================================================================================== -->
<!-- |    This document was autogenerated by xacro from optimo.urdf.xacro              | -->
<!-- |    EDITING THIS FILE BY HAND IS NOT RECOMMENDED                                 | -->
<!-- |    "already did :p" - Aaron                                                     | -->
<!-- =================================================================================== -->
<robot name="optimo">
  <material name="white">
    <color rgba="1.0 1.0 1.0 1.0"/>
  </material>
  <link name="world"/>
<joint name="world_to_link0" type="fixed">
    <parent link="world"/>
    <child link="optimo_link0"/>
    <origin rpy="0 0 0" xyz="0 0 .27"/>
  </joint>
  <link name="optimo_link0">
    <visual>
      <geometry>
        <mesh filename="package://meshes/optimo/J0_clean.stl"/>
      </geometry>
      <material name="white"/>
    </visual>
    <collision>
      <geometry>
        <mesh filename="package://meshes/optimo/col0.stl"/>
      </geometry>
    </collision>
    <inertial>
      <origin xyz="0 0 0"/>
      <mass value="1"/>
      <inertia ixx="0" ixy="0.0" ixz="0.0" iyy="0" iyz="0.0" izz="0"/>
    </inertial>
  </link>
  <joint name="optimo_joint1" type="revolute">
    <origin rpy="0 0 0" xyz="0 0 0"/>
    <parent link="optimo_link0"/>
    <child link="optimo_link1"/>
    <axis xyz="0 0 1"/>
    <limit effort="79" lower="-2.0943951012" upper="2.0943951012" velocity="10"/>
    <dynamics damping=".5" friction=".2"/>
  </joint>
  <link name="optimo_link1">
    <visual>
      <origin rpy="1.5707963267948966 0 0" xyz="0 0 0"/>
      <geometry>
        <mesh filename="package://meshes/optimo/J1_clean.stl"/>
      </geometry>
      <material name="white"/>
    </visual>
    <collision>
      <origin rpy="1.5707963267948966 0 0" xyz="0 0 0"/>
      <geometry>
        <mesh filename="package://meshes/optimo/col1.stl"/>
      </geometry>
    </collision>
    <inertial>
      <origin xyz="0 -0.01549 -0.01635 "/>
      <mass value="4.152"/>
      <inertia ixx="0.01" ixy="0" ixz="0" iyy="0.01" iyz="0" izz="0.006"/>
    </inertial>
  </link>
  <joint name="optimo_joint2" type="revolute">
    <origin rpy="1.5707963267948966 0 0" xyz="0 0 0"/>
    <parent link="optimo_link1"/>
    <child link="optimo_link2"/>
    <axis xyz="0 0 1"/>
    <limit effort="95" lower="1.13446401315" upper="3.40339203945" velocity="10"/>
    <dynamics damping=".5" friction=".2"/>
  </joint>
  <link name="optimo_link2">
    <visual>
      <origin rpy="1.5707963267948966 0 0" xyz="0 0 0.003"/>
      <geometry>
        <mesh filename="package://meshes/optimo/J2_clean.stl"/>
      </geometry>
      <material name="white"/>
    </visual>
    <collision>
      <origin rpy="1.5707963267948966 0 0" xyz="0 0 0"/>
      <geometry>
        <mesh filename="package://meshes/optimo/col2.stl"/>
      </geometry>
    </collision>
    <inertial>
      <origin xyz="0 -0.05677 -0.05063 "/>
      <mass value="1.72"/>
      <inertia ixx="0.004" ixy="0" ixz="0" iyy="0.003" iyz="0" izz="0.005"/>
    </inertial>
  </link>
  <joint name="optimo_joint3" type="revolute">
    <origin rpy="1.5707963267948966 0 0" xyz="0.0 -0.397 0.003"/>
    <parent link="optimo_link2"/>
    <child link="optimo_link3"/>
    <axis xyz="0 0 1"/>
    <limit effort="32" lower="-2.0943951012" upper="2.0943951012" velocity="10"/>
    <dynamics damping=".5" friction=".2"/>
  </joint>
  <link name="optimo_link3">
    <visual>
      <origin rpy="-1.5707963267948966 0 0" xyz="0 0 0"/>
      <geometry>
        <mesh filename="package://meshes/optimo/J3_clean.stl"/>
      </geometry>
      <material name="white"/>
    </visual>
    <collision>
      <origin rpy="-1.5707963267948966 0 0" xyz="0 0 0"/>
      <geometry>
        <mesh filename="package://meshes/optimo/col3.stl"/>
      </geometry>
    </collision>
    <inertial>
      <origin xyz="0 0 -0.098"/>
      <mass value="4.310"/>
      <inertia ixx="0.013" ixy="0" ixz="0" iyy="0.013" iyz="0" izz="0.003"/>
    </inertial>
  </link>
  <joint name="optimo_joint4" type="revolute">
    <origin rpy="-1.5707963267948966 0 0" xyz="0 0 0"/>
    <parent link="optimo_link3"/>
    <child link="optimo_link4"/>
    <axis xyz="0 0 1"/>
    <limit effort="40" lower="-2.4434609514" upper="0.08726646254999999" velocity="10"/>
    <dynamics damping=".5" friction=".2"/>
  </joint>
  <link name="optimo_link4">
    <visual>
      <origin rpy="1.5707963267948966 0 0" xyz="0 0 0"/>
      <geometry>
        <mesh filename="package://meshes/optimo/J4_clean.stl"/>
      </geometry>
      <material name="white"/>
    </visual>
    <collision>
      <origin rpy="1.5707963267948966 0 0" xyz="0 0 0"/>
      <geometry>
        <mesh filename="package://meshes/optimo/col4.stl"/>
      </geometry>
    </collision>
    <inertial>
      <origin xyz="-.00001 -0.0688 0.048852"/>
      <mass value="1.09"/>
      <inertia ixx="0.004" ixy="0" ixz="0" iyy="0.0008" iyz="0" izz="0.004"/>
    </inertial>
  </link>
  <joint name="optimo_joint5" type="revolute">
    <origin rpy="1.5707963267948966 0 0" xyz="0 -0.4 0"/>
    <parent link="optimo_link4"/>
    <child link="optimo_link5"/>
    <axis xyz="0 0 1"/>
    <limit effort="15" lower="-2.6179938765" upper="2.6179938765" velocity="10"/>
    <dynamics damping=".5" friction=".2"/>
  </joint>
  <link name="optimo_link5">
    <visual>
      <origin rpy="-1.5707963267948966 0 0" xyz="0 0 0"/>
      <geometry>
        <mesh filename="package://meshes/optimo/J5_clean.stl"/>
      </geometry>
      <material name="white"/>
    </visual>
    <collision>
      <origin rpy="-1.5707963267948966 0 0" xyz="0 0 0"/>
      <geometry>
        <mesh filename="package://meshes/optimo/col5.stl"/>
      </geometry>
    </collision>
    <inertial>
      <origin xyz="0 0.008 -.085"/>
      <mass value="2.23"/>
      <inertia ixx="0.005" ixy="0" ixz="0" iyy="0.005" iyz="0" izz="0.002"/>
    </inertial>
  </link>
  <joint name="optimo_joint6" type="revolute">
    <origin rpy="-1.5707963267948966 0 0" xyz="0 0 0"/>
    <parent link="optimo_link5"/>
    <child link="optimo_link6"/>
    <axis xyz="0 0 1"/>
    <limit effort="15" lower="-2.00712863865" upper="2.00712863865" velocity="10"/>
    <dynamics damping=".5" friction=".2"/>
  </joint>
  <link name="optimo_link6">
    <visual>
      <origin rpy="1.5707963267948966 0 0" xyz="0 0 0"/>
      <geometry>
        <mesh filename="package://meshes/optimo/J6_clean.stl"/>
      </geometry>
      <material name="white"/>
    </visual>
    <collision>
      <origin rpy="1.5707963267948966 0 0" xyz="0 0 0"/>
      <geometry>
        <mesh filename="package://meshes/optimo/col6.stl"/>
      </geometry>
    </collision>
    <inertial>
      <origin xyz="0  -0.010855 0"/>
      <mass value="1.138"/>
      <inertia ixx="0.0006" ixy="0" ixz="0" iyy="0.0006" iyz="0" izz="0.0005"/>
    </inertial>
  </link>
  <joint name="optimo_joint7" type="revolute">
    <origin rpy="1.5707963267948966 0 0" xyz="0 0 0"/>
    <parent link="optimo_link6"/>
    <child link="optimo_link7"/>
    <axis xyz="0 0 1"/>
    <limit effort="15" lower="-2.0943951012" upper="2.0943951012" velocity="10"/>
    <dynamics damping=".5" friction=".2"/>
  </joint>
  <link name="optimo_link7">
    <visual>
      <origin xyz="0.0 0.0 0.011"/>
      <geometry>
        <mesh filename="package://meshes/optimo/J7_clean.stl"/>
      </geometry>
      <material name="white"/>
    </visual>
    <collision>
      <geometry>
        <mesh filename="package://meshes/optimo/col7.stl"/>
      </geometry>
    </collision>
    <inertial>
      <origin xyz="0 0 0.0"/>
      <mass value=".88"/>
      <inertia ixx="0.0007" ixy="0" ixz="0" iyy="0.0007" iyz="0" izz="0.0003"/>
    </inertial>
  </link>

<!-- =================================================================================== -->
<!-- |                                  PLATO V2.1                                     | -->
<!-- =================================================================================== -->

  <!-- Link plato_base -->
  <link name="plato_base">
    <inertial>
      <origin xyz="-1.53511e-07 -0.0716474 0.00172334" rpy="0 0 0"/>
      <mass value="0.993448"/>
      <inertia ixx="0.00162041" ixy="-3.24339e-09" ixz="-3.49983e-09" iyy="0.000663019" iyz="0.000249986" izz="0.00158906"/>
    </inertial>
    <!-- Part plato_base -->
    <visual>
      <origin xyz="1.73472e-18 -5.55112e-17 -1.49186e-16" rpy="-2.22946e-26 -2.66572e-26 1.3174e-26"/>
      <geometry>
        <mesh filename="package://meshes/plato/plato_base.stl"/>
      </geometry>
      <material name="plato_base_material">
        <color rgba="0.917647 0.917647 0.917647 1"/>
      </material>
    </visual>
    <collision>
      <origin xyz="1.73472e-18 -5.55112e-17 -1.49186e-16" rpy="-2.22946e-26 -2.66572e-26 1.3174e-26"/>
      <geometry>
        <mesh filename="package://meshes/plato/plato_base.stl"/>
      </geometry>
    </collision>
  </link>
  <!-- Joint from optimo_link7 to plato_base -->
  <joint name="plato_base" type="fixed">
    <origin xyz="0 0 0.155" rpy="-1.5708 0 -1.5708"/>
    <parent link="optimo_link7"/>
    <child link="plato_base"/>
  </joint>

  <!-- Link plato_ee -->
  <link name="plato_ee">
    <inertial>
      <origin xyz="0 0 0" rpy="0 0 0"/>
      <mass value="1e-8"/>
      <inertia ixx="1e-8" ixy="0" ixz="0"
               iyy="1e-8" iyz="0" izz="1e-8"/>
    </inertial>
  </link>

  <joint name="plato_ee_joint" type="fixed">
    <origin rpy="0 0 0" xyz="0.0 -0.175 -0.07"/>
    <parent link="plato_base"/>
    <child link="plato_ee"/>
  </joint>

  <!-- Link plato_finger1_metacarpal -->
  <link name="plato_finger1_metacarpal">
    <inertial>
      <origin xyz="-6.08459e-11 0.0157721 -0.0225938" rpy="0 0 0"/>
      <mass value="0.128154"/>
      <inertia ixx="2.98623e-05" ixy="-4.15355e-14" ixz="1.06399e-13" iyy="3.45751e-05" iyz="7.6309e-07" izz="2.52647e-05"/>
    </inertial>
    <!-- Part plato_finger1_metacarpal -->
    <visual>
      <origin xyz="-8.67362e-18 -1.8735e-16 -2.98372e-16" rpy="1.5708 2.212e-77 1.8546e-68"/>
      <geometry>
        <mesh filename="package://meshes/plato/plato_finger1_metacarpal.stl"/>
      </geometry>
      <material name="plato_finger1_metacarpal_material">
        <color rgba="0.917647 0.917647 0.917647 1"/>
      </material>
    </visual>
    <collision>
      <origin xyz="-8.67362e-18 -1.8735e-16 -2.98372e-16" rpy="1.5708 2.212e-77 1.8546e-68"/>
      <geometry>
        <mesh filename="package://meshes/plato/plato_finger1_metacarpal.stl"/>
      </geometry>
    </collision>
  </link>
  <!-- Link plato_finger1_actuators -->
  <link name="plato_finger1_actuators">
    <inertial>
      <origin xyz="0.0148019 -4.94375e-11 -0.0226641" rpy="0 0 0"/>
      <mass value="0.274056"/>
      <inertia ixx="0.000181576" ixy="-1.69615e-14" ixz="1.14914e-06" iyy="6.13317e-05" iyz="-1.23312e-13" izz="0.00016059"/>
    </inertial>
    <!-- Part plato_finger1_actuators -->
    <visual>
      <origin xyz="8.57253e-19 0 0" rpy="0 -0 1.50653e-43"/>
      <geometry>
        <mesh filename="package://meshes/plato/plato_finger1_actuators.stl"/>
      </geometry>
      <material name="plato_finger1_actuators_material">
        <color rgba="0.917647 0.917647 0.917647 1"/>
      </material>
    </visual>
    <collision>
      <origin xyz="8.57253e-19 0 0" rpy="0 -0 1.50653e-43"/>
      <geometry>
        <mesh filename="package://meshes/plato/plato_finger1_actuators.stl"/>
      </geometry>
    </collision>
  </link>
  <!-- Link plato_finger1_link1 -->
  <link name="plato_finger1_link1">
    <inertial>
      <origin xyz="-0.0233359 9.15466e-08 -0.00730725" rpy="0 0 0"/>
      <mass value="0.0607448"/>
      <inertia ixx="4.06228e-06" ixy="7.80075e-11" ixz="-2.74097e-07" iyy="3.05761e-05" iyz="9.11964e-11" izz="3.04207e-05"/>
    </inertial>
    <!-- Part plato_finger1_link1 -->
    <visual>
      <origin xyz="0 0 0" rpy="1.5708 1.5708 0"/>
      <geometry>
        <mesh filename="package://meshes/plato/plato_finger1_link1.stl"/>
      </geometry>
      <material name="plato_finger1_link1_material">
        <color rgba="0.917647 0.917647 0.917647 1"/>
      </material>
    </visual>
    <collision>
      <origin xyz="0 0 0" rpy="1.5708 1.5708 0"/>
      <geometry>
        <mesh filename="package://meshes/plato/plato_finger1_link1.stl"/>
      </geometry>
    </collision>
  </link>
  <!-- Link plato_finger1_link2 -->
  <link name="plato_finger1_link2">
    <inertial>
      <origin xyz="-0.0368121 -2.24309e-05 -0.00299998" rpy="0 0 0"/>
      <mass value="0.054769"/>
      <inertia ixx="3.18679e-06" ixy="5.8235e-07" ixz="-9.12132e-11" iyy="1.92506e-05" iyz="6.92135e-11" izz="1.8357e-05"/>
    </inertial>
    <!-- Part plato_finger1_link2 -->
    <visual>
      <origin xyz="-0.0395 0.0012 0.01065" rpy="1.5708 1.5708 0"/>
      <geometry>
        <mesh filename="package://meshes/plato/plato_finger1_link2.stl"/>
      </geometry>
      <material name="plato_finger1_link2_material">
        <color rgba="0.917647 0.917647 0.917647 1"/>
      </material>
    </visual>
    <collision>
      <origin xyz="-0.0395 0.0012 0.01065" rpy="1.5708 1.5708 0"/>
      <geometry>
        <mesh filename="package://meshes/plato/plato_finger1_link2.stl"/>
      </geometry>
    </collision>
    <!-- Part finger_nail -->
    <visual>
      <origin xyz="-0.00596456 -0.0206712 -0.003" rpy="2.00713 1.5708 0"/>
      <geometry>
        <mesh filename="package://meshes/plato/finger_nail.stl"/>
      </geometry>
      <material name="finger_nail_material">
        <color rgba="0.529412 0.568627 0.6 1"/>
      </material>
    </visual>
    <collision>
      <origin xyz="-0.00596456 -0.0206712 -0.003" rpy="2.00713 1.5708 0"/>
      <geometry>
        <mesh filename="package://meshes/plato/finger_nail.stl"/>
      </geometry>
    </collision>
    <!-- Part gel_2x4_silicone -->
    <visual>
      <origin xyz="-0.0393241 0.001203 0.0106496" rpy="1.5708 1.5708 0"/>
      <geometry>
        <mesh filename="package://meshes/plato/gel_2x4_silicone.stl"/>
      </geometry>
      <material name="gel_2x4_silicone_material">
        <color rgba="0.647059 0.647059 0.647059 1"/>
      </material>
    </visual>
    <collision>
      <origin xyz="-0.0393241 0.001203 0.0106496" rpy="1.5708 1.5708 0"/>
      <geometry>
        <mesh filename="package://meshes/plato/gel_2x4_silicone.stl"/>
      </geometry>
    </collision>
  </link>
  <!-- Joint from plato_finger1_link1 to plato_finger1_link2 -->
  <joint name="plato_finger1_joint2" type="revolute">
    <origin xyz="-0.06 0 -0.0105" rpy="-3.14159 -5.51605e-30 4.59177e-41"/>
    <parent link="plato_finger1_link1"/>
    <child link="plato_finger1_link2"/>
    <axis xyz="0 0 1"/>
    <limit effort="10" velocity="10" lower="-2.0944" upper="1.0472"/>
  </joint>
  <!-- Joint from plato_finger1_actuators to plato_finger1_link1 -->
  <joint name="plato_finger1_joint1" type="revolute">
    <origin xyz="0.0305 -0.022 -0.0235" rpy="-1.5708 -0 1.5708"/>
    <parent link="plato_finger1_actuators"/>
    <child link="plato_finger1_link1"/>
    <axis xyz="0 0 1"/>
    <limit effort="10" velocity="10" lower="-1.0472" upper="1.0472"/>
  </joint>
  <!-- Joint from plato_finger1_metacarpal to plato_finger1_actuators -->
  <joint name="plato_finger1_actuators" type="revolute">
    <origin xyz="4.56881e-17 0.0315 -0.025" rpy="1.5708 -4.77399e-42 -9.95799e-17"/>
    <parent link="plato_finger1_metacarpal"/>
    <child link="plato_finger1_actuators"/>
    <axis xyz="0 0 1"/>
    <limit effort="10" velocity="10" lower="-1.5708" upper="1.5708"/>
  </joint>
  <!-- Joint from plato_base to plato_finger1_metacarpal -->
  <joint name="plato_finger1_metacarpal" type="revolute">
    <origin xyz="-1.42382e-10 -0.044 -0.0285" rpy="-1.5708 1.41781e-52 -1.81754e-27"/>
    <parent link="plato_base"/>
    <child link="plato_finger1_metacarpal"/>
    <axis xyz="0 0 1"/>
    <limit effort="10" velocity="10" lower="-0.785398" upper="0.785398"/>
  </joint>
  <!-- Link plato_finger2_link1 -->
  <link name="plato_finger2_link1">
    <inertial>
      <origin xyz="-0.0233359 9.15466e-08 -0.00730725" rpy="0 0 0"/>
      <mass value="0.0607448"/>
      <inertia ixx="4.06228e-06" ixy="7.80075e-11" ixz="-2.74097e-07" iyy="3.05761e-05" iyz="9.11964e-11" izz="3.04207e-05"/>
    </inertial>
    <!-- Part plato_finger2_link1 -->
    <visual>
      <origin xyz="0 0 0" rpy="1.5708 1.5708 0"/>
      <geometry>
        <mesh filename="package://meshes/plato/plato_finger2_link1.stl"/>
      </geometry>
      <material name="plato_finger2_link1_material">
        <color rgba="0.917647 0.917647 0.917647 1"/>
      </material>
    </visual>
    <collision>
      <origin xyz="0 0 0" rpy="1.5708 1.5708 0"/>
      <geometry>
        <mesh filename="package://meshes/plato/plato_finger2_link1.stl"/>
      </geometry>
    </collision>
  </link>
  <!-- Link plato_finger2_link2 -->
  <link name="plato_finger2_link2">
    <inertial>
      <origin xyz="-0.0368138 1.97334e-05 -0.00300054" rpy="0 0 0"/>
      <mass value="0.0547792"/>
      <inertia ixx="3.18727e-06" ixy="-5.8484e-07" ixz="2.179e-10" iyy="1.92547e-05" iyz="-1.08224e-10" izz="1.83601e-05"/>
    </inertial>
    <!-- Part finger_nail_2 -->
    <visual>
      <origin xyz="-0.00608548 0.020339 -0.00299995" rpy="1.5708 -1.5708 -2.70526"/>
      <geometry>
        <mesh filename="package://meshes/plato/finger_nail.stl"/>
      </geometry>
      <material name="finger_nail_2_material">
        <color rgba="0.529412 0.568627 0.6 1"/>
      </material>
    </visual>
    <collision>
      <origin xyz="-0.00608548 0.020339 -0.00299995" rpy="1.5708 -1.5708 -2.70526"/>
      <geometry>
        <mesh filename="package://meshes/plato/finger_nail.stl"/>
      </geometry>
    </collision>
    <!-- Part plato_finger2_link2 -->
    <visual>
      <origin xyz="-0.0395 -0.0012 -0.01665" rpy="-1.5708 -1.5708 0"/>
      <geometry>
        <mesh filename="package://meshes/plato/plato_finger2_link2.stl"/>
      </geometry>
      <material name="plato_finger2_link2_material">
        <color rgba="0.917647 0.917647 0.917647 1"/>
      </material>
    </visual>
    <collision>
      <origin xyz="-0.0395 -0.0012 -0.01665" rpy="-1.5708 -1.5708 0"/>
      <geometry>
        <mesh filename="package://meshes/plato/plato_finger2_link2.stl"/>
      </geometry>
    </collision>
    <!-- Part gel_2x4_silicone_2 -->
    <visual>
      <origin xyz="-0.0393219 -0.001203 -0.0166496" rpy="-1.5708 -1.5708 0"/>
      <geometry>
        <mesh filename="package://meshes/plato/gel_2x4_silicone.stl"/>
      </geometry>
      <material name="gel_2x4_silicone_2_material">
        <color rgba="0.647059 0.647059 0.647059 1"/>
      </material>
    </visual>
    <collision>
      <origin xyz="-0.0393219 -0.001203 -0.0166496" rpy="-1.5708 -1.5708 0"/>
      <geometry>
        <mesh filename="package://meshes/plato/gel_2x4_silicone.stl"/>
      </geometry>
    </collision>
  </link>
  <!-- Joint from plato_finger2_link1 to plato_finger2_link2 -->
  <joint name="plato_finger2_joint2" type="revolute">
    <origin xyz="-0.06 -1.73472e-18 -0.0105" rpy="-3.14159 -5.81785e-30 0"/>
    <parent link="plato_finger2_link1"/>
    <child link="plato_finger2_link2"/>
    <axis xyz="0 0 1"/>
    <limit effort="10" velocity="10" lower="-1.0472" upper="2.0944"/>
  </joint>
  <!-- Joint from plato_base to plato_finger2_link1 -->
  <joint name="plato_finger2_joint1" type="revolute">
    <origin xyz="0.0305 -0.113 0.0145" rpy="-1.5708 -1.56015e-25 1.5708"/>
    <parent link="plato_base"/>
    <child link="plato_finger2_link1"/>
    <axis xyz="0 0 1"/>
    <limit effort="10" velocity="10" lower="-1.0472" upper="1.0472"/>
  </joint>
  <!-- Link plato_finger3_link1 -->
  <link name="plato_finger3_link1">
    <inertial>
      <origin xyz="-0.0233359 9.15466e-08 -0.00730725" rpy="0 0 0"/>
      <mass value="0.0607448"/>
      <inertia ixx="4.06228e-06" ixy="7.80075e-11" ixz="-2.74097e-07" iyy="3.05761e-05" iyz="9.11964e-11" izz="3.04207e-05"/>
    </inertial>
    <!-- Part plato_finger3_link1 -->
    <visual>
      <origin xyz="0 0 0" rpy="1.5708 1.5708 0"/>
      <geometry>
        <mesh filename="package://meshes/plato/plato_finger3_link1.stl"/>
      </geometry>
      <material name="plato_finger3_link1_material">
        <color rgba="0.917647 0.917647 0.917647 1"/>
      </material>
    </visual>
    <collision>
      <origin xyz="0 0 0" rpy="1.5708 1.5708 0"/>
      <geometry>
        <mesh filename="package://meshes/plato/plato_finger3_link1.stl"/>
      </geometry>
    </collision>
  </link>
  <!-- Link plato_finger3_link2 -->
  <link name="plato_finger3_link2">
    <inertial>
      <origin xyz="-0.0368127 2.08487e-05 -0.00300002" rpy="0 0 0"/>
      <mass value="0.054769"/>
      <inertia ixx="3.18614e-06" ixy="-5.84424e-07" ixz="9.12334e-11" iyy="1.92522e-05" iyz="6.8963e-11" izz="1.8358e-05"/>
    </inertial>
    <!-- Part finger_nail_3 -->
    <visual>
      <origin xyz="-0.00608548 0.020339 -0.00300005" rpy="-1.5708 -1.5708 0.436332"/>
      <geometry>
        <mesh filename="package://meshes/plato/finger_nail.stl"/>
      </geometry>
      <material name="finger_nail_3_material">
        <color rgba="0.529412 0.568627 0.6 1"/>
      </material>
    </visual>
    <collision>
      <origin xyz="-0.00608548 0.020339 -0.00300005" rpy="-1.5708 -1.5708 0.436332"/>
      <geometry>
        <mesh filename="package://meshes/plato/finger_nail.stl"/>
      </geometry>
    </collision>
    <!-- Part gel_2x4_silicone_3 -->
    <visual>
      <origin xyz="-0.0393241 -0.001203 -0.0166496" rpy="-1.5708 -1.5708 0"/>
      <geometry>
        <mesh filename="package://meshes/plato/gel_2x4_silicone.stl"/>
      </geometry>
      <material name="gel_2x4_silicone_3_material">
        <color rgba="0.647059 0.647059 0.647059 1"/>
      </material>
    </visual>
    <collision>
      <origin xyz="-0.0393241 -0.001203 -0.0166496" rpy="-1.5708 -1.5708 0"/>
      <geometry>
        <mesh filename="package://meshes/plato/gel_2x4_silicone.stl"/>
      </geometry>
    </collision>
    <!-- Part plato_finger3_link2 -->
    <visual>
      <origin xyz="-0.0395 -0.0012 -0.01665" rpy="-1.5708 -1.5708 0"/>
      <geometry>
        <mesh filename="package://meshes/plato/plato_finger3_link2.stl"/>
      </geometry>
      <material name="plato_finger3_link2_material">
        <color rgba="0.917647 0.917647 0.917647 1"/>
      </material>
    </visual>
    <collision>
      <origin xyz="-0.0395 -0.0012 -0.01665" rpy="-1.5708 -1.5708 0"/>
      <geometry>
        <mesh filename="package://meshes/plato/plato_finger3_link2.stl"/>
      </geometry>
    </collision>
  </link>
  <!-- Joint from plato_finger3_link1 to plato_finger3_link2 -->
  <joint name="plato_finger3_joint2" type="revolute">
    <origin xyz="-0.06 -1.73472e-18 -0.0045" rpy="-1.97215e-31 -6.06437e-30 9.18355e-41"/>
    <parent link="plato_finger3_link1"/>
    <child link="plato_finger3_link2"/>
    <axis xyz="0 0 1"/>
    <limit effort="10" velocity="10" lower="-1.0472" upper="2.0944"/>
  </joint>
  <!-- Joint from plato_base to plato_finger3_link1 -->
  <joint name="plato_finger3_joint1" type="revolute">
    <origin xyz="-0.0305 -0.113 0.0145" rpy="1.5708 -1.56015e-25 1.5708"/>
    <parent link="plato_base"/>
    <child link="plato_finger3_link1"/>
    <axis xyz="0 0 1"/>
    <limit effort="10" velocity="10" lower="-1.0472" upper="1.0472"/>
  </joint>
</robot>